Workbook

Sheet Legend
A1: Role assignments — hitters
A3: WHAT TO EDIT — the yellow cells on the Assignments sheet:
A4: * One probability per role column. They should sum to 1.00 for each player; the 'Role Prob Sum' column checks this.
A5: * Role Start — when the player takes the job (see the Timing table on the Roles sheet).
A6: * Availability — YOURS to set: the share of the season you expect him healthy and on an MLB roster. 1.00 = full year.
A7: * Exp Apps / IP/App (pitchers) — how often he is handed the ball, and how long he stays. His innings are the two multiplied, so for a pitcher AVAILABILITY IS EXP APPS: it is not a multiplier on this sheet and Durability stays 1.00 for him.
A8: * Durability — the model's, from his own games-played record against others in the same role. Centred on 1.00 and allowed to go above it: a player who misses nothing beats the league-average missed time his role's anchor was built from. Overwrite it if you disagree; Proj PA multiplies both.
A9: * Pos / Bats (or Throws) — needed for the typed-slot allocation and the platoon splits.
A11: WHY PROBABILITIES AND NOT ONE ROLE:
A12: A player in a job battle is ~50% full-time / 30% platoon / 20% bench. Picking one label
A13: yields a plausible-looking PA figure that is the mean of a bimodal distribution — wrong in
A14: both worlds. Probabilities also give the model the variance, which is what season-long
... A48: cross-role ORDERING is more reliable than the absolute numbers.

Sheet Assignments
A1: PlayerId | B1: Name | C1: Team | D1: Age | E1: Bats | F1: Pos | G1: Last PA | H1: Career | I1: Suggested Role | J1: Role Start | K1: Role Share | L1: Availability | M1: Durability | N1: Full Time | O1: Everyday DH / 1B-DH | P1: Strong Side Platoon | Q1: Weak Side Platoon | R1: Catcher - Primary | S1: Catcher - Tandem | T1: Catcher - Backup | U1: Utility IF | V1: Utility OF / 4th OF | W1: Bench Bat | X1: Injury Replacement / 26th Man | Y1: Depth (no MLB PA) | Z1: Proj PA | AA1: Role Prob Sum | AB1: Proj vL Share | AC1: Notes
A2: ANCHORS -> | N2: 630 | O2: 600 | P2: 480 | Q2: 230 | R2: 500 | S2: 340 | T2: 180 | U2: 290 | V2: 300 | W2: 150 | X2: 90 | Y2: 1 | Z2: <- PA per 162 G at full availability
A3: anchor:vl_lhb | N3: 0.26 | O3: 0.26 | P3: 0.12 | Q3: 0.08 | R3: 0.26 | S3: 0.22 | T3: 0.24 | U3: 0.26 | V3: 0.24 | W3: 0.22 | X3: 0.26 | Y3: 0.26
A4: anchor:vl_rhb | N4: 0.29 | O4: 0.29 | P4: 0.45 | Q4: 0.68 | R4: 0.29 | S4: 0.38 | T4: 0.33 | U4: 0.31 | V4: 0.33 | W4: 0.36 | X4: 0.29 | Y4: 0.29
A5: 999999 | B5: EXAMPLE — delete this row | C5: FA | D5: 28 | E5: R | F5: 2B | I5: Full Time | J5: Early Season (~May) | K5: =IFERROR(INDEX(Roles!$B$17:$B$20,MATCH(J5,Roles!$A$17:$A$20,0)),1) | L5: 0.85 | M5: 0.92 | N5: 0.6 | P5: 0.3 | U5: 0.1 | Z5: =SUMPRODUCT(N5:Y5,$N$2:$Y$2)*$K5*$L5*$M5 | AA5: =SUM(N5:Y5) | AB5: =IFERROR(IF(UPPER($E5)="L",SUMPRODUCT(N5:Y5,$N$3:$Y$3,$N$2:$Y$2),SUMPRODUCT(N5:Y5,$N$4:$Y$4,$N$2:$Y$2))/(Z5/($K5*$L5*$M5)),"") | AC5: Unsigned; job battle. 60% full-time / 30% strong-side platoon / 10% utility. Missed April, and his own games-played record runs a little short of his role's.
A6: 592450 | B6: Aaron Judge | C6: NYY | D6: 35 | E6: R | F6: RF | G6: 285 | H6: 2822 | I6: Full Time | J6: Opening Day | K6: =IFERROR(INDEX(Roles!$B$17:$B$20,MATCH(J6,Roles!$A$17:$A$20,0)),1) | L6: 1 | M6: 0.9355526 | N6: 1 | Z6: =SUMPRODUCT(N6:Y6,$N$2:$Y$2)*$K6*$L6*$M6 | AA6: =SUM(N6:Y6) | AB6: =IFERROR(IF(UPPER($E6)="L",SUMPRODUCT(N6:Y6,$N$3:$Y$3,$N$2:$Y$2),SUMPRODUCT(N6:Y6,$N$4:$Y$4,$N$2:$Y$2))/(Z6/($K6*$L6*$M6)),"")
A7: 680664 | B7: Eduardo Valencia | C7: DET | D7: 27 | E7: R | F7: C | G7: 138 | H7: 138 | I7: Bench Bat | J7: Opening Day | K7: =IFERROR(INDEX(Roles!$B$17:$B$20,MATCH(J7,Roles!$A$17:$A$20,0)),1) | L7: 1 | M7: 1 | U7: 0.4 | W7: 0.6 | Z7: =SUMPRODUCT(N7:Y7,$N$2:$Y$2)*$K7*$L7*$M7 | AA7: =SUM(N7:Y7) | AB7: =IFERROR(IF(UPPER($E7)="L",SUMPRODUCT(N7:Y7,$N$3:$Y$3,$N$2:$Y$2),SUMPRODUCT(N7:Y7,$N$4:$Y$4,$N$2:$Y$2))/(Z7/($K7*$L7*$M7)),"")
A8: 691002 | B8: Yohandy Morales | C8: WSH | D8: 26 | E8: R | F8: 1B | G8: 47 | H8: 47 | I8: Weak Side Platoon | J8: Opening Day | K8: =IFERROR(INDEX(Roles!$B$17:$B$20,MATCH(J8,Roles!$A$17:$A$20,0)),1) | L8: 1 | M8: 1 | Q8: 0.6 | U8: 0.4 | Z8: =SUMPRODUCT(N8:Y8,$N$2:$Y$2)*$K8*$L8*$M8 | AA8: =SUM(N8:Y8) | AB8: =IFERROR(IF(UPPER($E8)="L",SUMPRODUCT(N8:Y8,$N$3:$Y$3,$N$2:$Y$2),SUMPRODUCT(N8:Y8,$N$4:$Y$4,$N$2:$Y$2))/(Z8/($K8*$L8*$M8)),"")
A9: 804668 | B9: Rafael Flores Jr. | C9: PIT | D9: 26 | E9: R | F9: C | G9: 163 | H9: 180 | I9: Catcher - Primary | J9: Opening Day | K9: =IFERROR(INDEX(Roles!$B$17:$B$20,MATCH(J9,Roles!$A$17:$A$20,0)),1) | L9: 1 | M9: 1 | R9: 0.75 | S9: 0.25 | Z9: =SUMPRODUCT(N9:Y9,$N$2:$Y$2)*$K9*$L9*$M9 | AA9: =SUM(N9:Y9) | AB9: =IFERROR(IF(UPPER($E9)="L",SUMPRODUCT(N9:Y9,$N$3:$Y$3,$N$2:$Y$2),SUMPRODUCT(N9:Y9,$N$4:$Y$4,$N$2:$Y$2))/(Z9/($K9*$L9*$M9)),"")
A10: 660271 | B10: Shohei Ohtani | C10: LAD | D10: 32 | E10: L | F10: P | G10: 618 | H10: 3341 | I10: Everyday DH / 1B-DH | J10: Opening Day | K10: =IFERROR(INDEX(Roles!$B$17:$B$20,MATCH(J10,Roles!$A$17:$A$20,0)),1) | L10: 1 | M10: 1.1150872 | O10: 1 | Z10: =SUMPRODUCT(N10:Y10,$N$2:$Y$2)*$K10*$L10*$M10 | AA10: =SUM(N10:Y10) | AB10: =IFERROR(IF(UPPER($E10)="L",SUMPRODUCT(N10:Y10,$N$3:$Y$3,$N$2:$Y$2),SUMPRODUCT(N10:Y10,$N$4:$Y$4,$N$2:$Y$2))/(Z10/($K10*$L10*$M10)),"")
A11: 663728 | B11: Cal Raleigh | C11: SEA | D11: 30 | E11: S | F11: C | G11: 530 | H11: 2847 | I11: Catcher - Primary | J11: Opening Day | K11: =IFERROR(INDEX(Roles!$B$17:$B$20,MATCH(J11,Roles!$A$17:$A$20,0)),1) | L11: 1 | M11: 1.15 | R11: 1 | Z11: =SUMPRODUCT(N11:Y11,$N$2:$Y$2)*$K11*$L11*$M11 | AA11: =SUM(N11:Y11) | AB11: =IFERROR(IF(UPPER($E11)="L",SUMPRODUCT(N11:Y11,$N$3:$Y$3,$N$2:$Y$2),SUMPRODUCT(N11:Y11,$N$4:$Y$4,$N$2:$Y$2))/(Z11/($K11*$L11*$M11)),"")
A12: 519317 | B12: Giancarlo Stanton | C12: NYY | D12: 37 | E12: R | F12: RF | G12: 96 | H12: 1703 | I12: Full Time | J12: Opening Day | K12: =IFERROR(INDEX(Roles!$B$17:$B$20,MATCH(J12,Roles!$A$17:$A$20,0)),1) | L12: 1 | M12: 0.64061847 | N12: 1 | Z12: =SUMPRODUCT(N12:Y12,$N$2:$Y$2)*$K12*$L12*$M12 | AA12: =SUM(N12:Y12) | AB12: =IFERROR(IF(UPPER($E12)="L",SUMPRODUCT(N12:Y12,$N$3:$Y$3,$N$2:$Y$2),SUMPRODUCT(N12:Y12,$N$4:$Y$4,$N$2:$Y$2))/(Z12/($K12*$L12*$M12)),"")
A13: 656941 | B13: Kyle Schwarber | C13: PHI | D13: 34 | E13: L | F13: 1B | G13: 701 | H13: 3506 | I13: Everyday DH / 1B-DH | J13: Opening Day | K13: =IFERROR(INDEX(Roles!$B$17:$B$20,MATCH(J13,Roles!$A$17:$A$20,0)),1) | L13: 1 | M13: 1.15 | O13: 1 | Z13: =SUMPRODUCT(N13:Y13,$N$2:$Y$2)*$K13*$L13*$M13 | AA13: =SUM(N13:Y13) | AB13: =IFERROR(IF(UPPER($E13)="L",SUMPRODUCT(N13:Y13,$N$3:$Y$3,$N$2:$Y$2),SUMPRODUCT(N13:Y13,$N$4:$Y$4,$N$2:$Y$2))/(Z13/($K13*$L13*$M13)),"")
A14: 608596 | B14: Tom Murphy | C14: SF | D14: 36 | E14: R | F14: C | G14: 38 | H14: 239 | I14: Depth (no MLB PA) | J14: Opening Day | K14: =IFERROR(INDEX(Roles!$B$17:$B$20,MATCH(J14,Roles!$A$17:$A$20,0)),1) | L14: 1 | M14: 1 | Y14: 1 | Z14: =SUMPRODUCT(N14:Y14,$N$2:$Y$2)*$K14*$L14*$M14 | AA14: =SUM(N14:Y14) | AB14: =IFERROR(IF(UPPER($E14)="L",SUMPRODUCT(N14:Y14,$N$3:$Y$3,$N$2:$Y$2),SUMPRODUCT(N14:Y14,$N$4:$Y$4,$N$2:$Y$2))/(Z14/($K14*$L14*$M14)),"")
A15: 680837 | B15: Ryan Fitzgerald | C15: MIN | D15: 33 | E15: L | F15: SS | G15: 53 | H15: 53 | I15: Bench Bat | J15: Opening Day | K15: =IFERROR(INDEX(Roles!$B$17:$B$20,MATCH(J15,Roles!$A$17:$A$20,0)),1) | L15: 1 | M15: 1 | W15: 1 | Z15: =SUMPRODUCT(N15:Y15,$N$2:$Y$2)*$K15*$L15*$M15 | AA15: =SUM(N15:Y15) | AB15: =IFERROR(IF(UPPER($E15)="L",SUMPRODUCT(N15:Y15,$N$3:$Y$3,$N$2:$Y$2),SUMPRODUCT(N15:Y15,$N$4:$Y$4,$N$2:$Y$2))/(Z15/($K15*$L15*$M15)),"")
A16: 665742 | B16: Juan Soto | C16: NYM | D16: 28 | E16: L | F16: LF | G16: 482 | H16: 3282 | I16: Full Time | J16: Opening Day | K16: =IFERROR(INDEX(Roles!$B$17:$B$20,MATCH(J16,Roles!$A$17:$A$20,0)),1) | L16: 1 | M16: 1.057946 | N16: 1 | Z16: =SUMPRODUCT(N16:Y16,$N$2:$Y$2)*$K16*$L16*$M16 | AA16: =SUM(N16:Y16) | AB16: =IFERROR(IF(UPPER($E16)="L",SUMPRODUCT(N16:Y16,$N$3:$Y$3,$N$2:$Y$2),SUMPRODUCT(N16:Y16,$N$4:$Y$4,$N$2:$Y$2))/(Z16/($K16*$L16*$M16)),"")
A17: 621439 | B17: Byron Buxton | C17: MIN | D17: 33 | E17: R | F17: CF | G17: 408 | H17: 2067 | I17: Full Time | J17: Opening Day | K17: =IFERROR(INDEX(Roles!$B$17:$B$20,MATCH(J17,Roles!$A$17:$A$20,0)),1) | L17: 1 | M17: 0.90835406 | N17: 1 | Z17: =SUMPRODUCT(N17:Y17,$N$2:$Y$2)*$K17*$L17*$M17 | AA17: =SUM(N17:Y17) | AB17: =IFERROR(IF(UPPER($E17)="L",SUMPRODUCT(N17:Y17,$N$3:$Y$3,$N$2:$Y$2),SUMPRODUCT(N17:Y17,$N$4:$Y$4,$N$2:$Y$2))/(Z17/($K17*$L17*$M17)),"")
A18: 808959 | B18: Munetaka Murakami | C18: CWS | D18: 27 | E18: L | F18: 1B | G18: 553 | H18: 553 | I18: Full Time | J18: Opening Day | K18: =IFERROR(INDEX(Roles!$B$17:$B$20,MATCH(J18,Roles!$A$17:$A$20,0)),1) | L18: 1 | M18: 0.97986885 | N18: 1 | Z18: =SUMPRODUCT(N18:Y18,$N$2:$Y$2)*$K18*$L18*$M18 | AA18: =SUM(N18:Y18) | AB18: =IFERROR(IF(UPPER($E18)="L",SUMPRODUCT(N18:Y18,$N$3:$Y$3,$N$2:$Y$2),SUMPRODUCT(N18:Y18,$N$4:$Y$4,$N$2:$Y$2))/(Z18/($K18*$L18*$M18)),"")
A19: 695491 | B19: Joshua Báez | C19: STL | D19: 24 | E19: R | F19: LF | G19: 108 | H19: 108 | I19: Bench Bat | J19: Opening Day | K19: =IFERROR(INDEX(Roles!$B$17:$B$20,MATCH(J19,Roles!$A$17:$A$20,0)),1) | L19: 1 | M19: 1 | W19: 0.85 | X19: 0.15 | Z19: =SUMPRODUCT(N19:Y19,$N$2:$Y$2)*$K19*$L19*$M19 | AA19: =SUM(N19:Y19) | AB19: =IFERROR(IF(UPPER($E19)="L",SUMPRODUCT(N19:Y19,$N$3:$Y$3,$N$2:$Y$2),SUMPRODUCT(N19:Y19,$N$4:$Y$4,$N$2:$Y$2))/(Z19/($K19*$L19*$M19)),"")
A20: 624413 | B20: Pete Alonso | C20: BAL | D20: 32 | E20: R | F20: 1B | G20: 700 | H20: 3447 | I20: Full Time | J20: Opening Day | K20: =IFERROR(INDEX(Roles!$B$17:$B$20,MATCH(J20,Roles!$A$17:$A$20,0)),1) | L20: 1 | M20: 1.15 | N20: 1 | Z20: =SUMPRODUCT(N20:Y20,$N$2:$Y$2)*$K20*$L20*$M20 | AA20: =SUM(N20:Y20) | AB20: =IFERROR(IF(UPPER($E20)="L",SUMPRODUCT(N20:Y20,$N$3:$Y$3,$N$2:$Y$2),SUMPRODUCT(N20:Y20,$N$4:$Y$4,$N$2:$Y$2))/(Z20/($K20*$L20*$M20)),"")
A21: 699013 | B21: Esmerlyn Valdez | C21: PIT | D21: 23 | E21: R | F21: RF | G21: 287 | H21: 287 | I21: Bench Bat | J21: Opening Day | K21: =IFERROR(INDEX(Roles!$B$17:$B$20,MATCH(J21,Roles!$A$17:$A$20,0)),1) | L21: 1 | M21: 1 | N21: 0.4 | W21: 0.6 | Z21: =SUMPRODUCT(N21:Y21,$N$2:$Y$2)*$K21*$L21*$M21 | AA21: =SUM(N21:Y21) | AB21: =IFERROR(IF(UPPER($E21)="L",SUMPRODUCT(N21:Y21,$N$3:$Y$3,$N$2:$Y$2),SUMPRODUCT(N21:Y21,$N$4:$Y$4,$N$2:$Y$2))/(Z21/($K21*$L21*$M21)),"")
A22: 621550 | B22: Patrick Wisdom | C22: SEA | D22: 35 | E22: R | F22: 3B | G22: 50 | H22: 1060 | I22: Weak Side Platoon | J22: Opening Day | K22: =IFERROR(INDEX(Roles!$B$17:$B$20,MATCH(J22,Roles!$A$17:$A$20,0)),1) | L22: 1 | M22: 1 | Q22: 1 | Z22: =SUMPRODUCT(N22:Y22,$N$2:$Y$2)*$K22*$L22*$M22 | AA22: =SUM(N22:Y22) | AB22: =IFERROR(IF(UPPER($E22)="L",SUMPRODUCT(N22:Y22,$N$3:$Y$3,$N$2:$Y$2),SUMPRODUCT(N22:Y22,$N$4:$Y$4,$N$2:$Y$2))/(Z22/($K22*$L22*$M22)),"")
A23: 666703 | B23: Eguy Rosario | C23: SD | D23: 27 | E23: R | F23: 3B | G23: 57 | H23: 100 | I23: Depth (no MLB PA) | J23: Opening Day | K23: =IFERROR(INDEX(Roles!$B$17:$B$20,MATCH(J23,Roles!$A$17:$A$20,0)),1) | L23: 1 | M23: 1 | Y23: 1 | Z23: =SUMPRODUCT(N23:Y23,$N$2:$Y$2)*$K23*$L23*$M23 | AA23: =SUM(N23:Y23) | AB23: =IFERROR(IF(UPPER($E23)="L",SUMPRODUCT(N23:Y23,$N$3:$Y$3,$N$2:$Y$2),SUMPRODUCT(N23:Y23,$N$4:$Y$4,$N$2:$Y$2))/(Z23/($K23*$L23*$M23)),"")
A24: 828599 | B24: Lucas Spence | C24: HOU | D24: 24 | E24: L | F24: CF | G24: 63 | H24: 63 | I24: Full Time | J24: Opening Day | K24: =IFERROR(INDEX(Roles!$B$17:$B$20,MATCH(J24,Roles!$A$17:$A$20,0)),1) | L24: 1 | M24: 1 | N24: 0.6 | V24: 0.4 | Z24: =SUMPRODUCT(N24:Y24,$N$2:$Y$2)*$K24*$L24*$M24 | AA24: =SUM(N24:Y24) | AB24: =IFERROR(IF(UPPER($E24)="L",SUMPRODUCT(N24:Y24,$N$3:$Y$3,$N$2:$Y$2),SUMPRODUCT(N24:Y24,$N$4:$Y$4,$N$2:$Y$2))/(Z24/($K24*$L24*$M24)),"")
A25: 608369 | B25: Corey Seager | C25: TEX | D25: 33 | E25: L | F25: SS | G25: 436 | H25: 2613 | I25: Full Time | J25: Opening Day | K25: =IFERROR(INDEX(Roles!$B$17:$B$20,MATCH(J25,Roles!$A$17:$A$20,0)),1) | L25: 1 | M25: 0.91090392 | N25: 1 | Z25: =SUMPRODUCT(N25:Y25,$N$2:$Y$2)*$K25*$L25*$M25 | AA25: =SUM(N25:Y25) | AB25: =IFERROR(IF(UPPER($E25)="L",SUMPRODUCT(N25:Y25,$N$3:$Y$3,$N$2:$Y$2),SUMPRODUCT(N25:Y25,$N$4:$Y$4,$N$2:$Y$2))/(Z25/($K25*$L25*$M25)),"")
A26: 691406 | B26: Junior Caminero | C26: TB | D26: 23 | E26: R | F26: 3B | G26: 702 | H26: 1568 | I26: Full Time | J26: Opening Day | K26: =IFERROR(INDEX(Roles!$B$17:$B$20,MATCH(J26,Roles!$A$17:$A$20,0)),1) | L26: 1 | M26: 1.0885444 | N26: 1 | Z26: =SUMPRODUCT(N26:Y26,$N$2:$Y$2)*$K26*$L26*$M26 | AA26: =SUM(N26:Y26) | AB26: =IFERROR(IF(UPPER($E26)="L",SUMPRODUCT(N26:Y26,$N$3:$Y$3,$N$2:$Y$2),SUMPRODUCT(N26:Y26,$N$4:$Y$4,$N$2:$Y$2))/(Z26/($K26*$L26*$M26)),"")
A27: 670541 | B27: Yordan Alvarez | C27: HOU | D27: 30 | E27: L | F27: LF | G27: 692 | H27: 2583 | I27: Everyday DH / 1B-DH | J27: Opening Day | K27: =IFERROR(INDEX(Roles!$B$17:$B$20,MATCH(J27,Roles!$A$17:$A$20,0)),1) | L27: 1 | M27: 0.98063845 | O27: 1 | Z27: =SUMPRODUCT(N27:Y27,$N$2:$Y$2)*$K27*$L27*$M27 | AA27: =SUM(N27:Y27) | AB27: =IFERROR(IF(UPPER($E27)="L",SUMPRODUCT(N27:Y27,$N$3:$Y$3,$N$2:$Y$2),SUMPRODUCT(N27:Y27,$N$4:$Y$4,$N$2:$Y$2))/(Z27/($K27*$L27*$M27)),"")
A28: 696100 | B28: Hunter Goodman | C28: COL | D28: 27 | E28: R | F28: C | G28: 574 | H28: 1454 | I28: Catcher - Primary | J28: Opening Day | K28: =IFERROR(INDEX(Roles!$B$17:$B$20,MATCH(J28,Roles!$A$17:$A$20,0)),1) | L28: 1 | M28: 1.0993046 | R28: 1 | Z28: =SUMPRODUCT(N28:Y28,$N$2:$Y$2)*$K28*$L28*$M28 | AA28: =SUM(N28:Y28) | AB28: =IFERROR(IF(UPPER($E28)="L",SUMPRODUCT(N28:Y28,$N$3:$Y$3,$N$2:$Y$2),SUMPRODUCT(N28:Y28,$N$4:$Y$4,$N$2:$Y$2))/(Z28/($K28*$L28*$M28)),"")
A29: 681481 | B29: Kerry Carpenter | C29: DET | D29: 29 | E29: L | F29: RF | G29: 259 | H29: 1591 | I29: Bench Bat | J29: Opening Day | K29: =IFERROR(INDEX(Roles!$B$17:$B$20,MATCH(J29,Roles!$A$17:$A$20,0)),1) | L29: 1 | M29: 1.0328381 | W29: 0.85 | X29: 0.15 | Z29: =SUMPRODUCT(N29:Y29,$N$2:$Y$2)*$K29*$L29*$M29 | AA29: =SUM(N29:Y29) | AB29: =IFERROR(IF(UPPER($E29)="L",SUMPRODUCT(N29:Y29,$N$3:$Y$3,$N$2:$Y$2),SUMPRODUCT(N29:Y29,$N$4:$Y$4,$N$2:$Y$2))/(Z29/($K29*$L29*$M29)),"")
A30: 695657 | B30: Colson Montgomery | C30: CWS | D30: 25 | E30: L | F30: SS | G30: 638 | H30: 922 | I30: Full Time | J30: Opening Day | K30: =IFERROR(INDEX(Roles!$B$17:$B$20,MATCH(J30,Roles!$A$17:$A$20,0)),1) | L30: 1 | M30: 1.0047621 | N30: 1 | Z30: =SUMPRODUCT(N30:Y30,$N$2:$Y$2)*$K30*$L30*$M30 | AA30: =SUM(N30:Y30) | AB30: =IFERROR(IF(UPPER($E30)="L",SUMPRODUCT(N30:Y30,$N$3:$Y$3,$N$2:$Y$2),SUMPRODUCT(N30:Y30,$N$4:$Y$4,$N$2:$Y$2))/(Z30/($K30*$L30*$M30)),"")
A31: 700250 | B31: Ben Rice | C31: NYY | D31: 28 | E31: L | F31: 1B | G31: 667 | H31: 1375 | I31: Everyday DH / 1B-DH | J31: Opening Day | K31: =IFERROR(INDEX(Roles!$B$17:$B$20,MATCH(J31,Roles!$A$17:$A$20,0)),1) | L31: 1 | M31: 1.0254547 | O31: 1 | Z31: =SUMPRODUCT(N31:Y31,$N$2:$Y$2)*$K31*$L31*$M31 | AA31: =SUM(N31:Y31) | AB31: =IFERROR(IF(UPPER($E31)="L",SUMPRODUCT(N31:Y31,$N$3:$Y$3,$N$2:$Y$2),SUMPRODUCT(N31:Y31,$N$4:$Y$4,$N$2:$Y$2))/(Z31/($K31*$L31*$M31)),"")
A32: 678577 | B32: Junior Perez | C32: CWS | D32: 25 | E32: R | F32: LF | G32: 36 | H32: 36 | I32: Injury Replacement / 26th Man | J32: Opening Day | K32: =IFERROR(INDEX(Roles!$B$17:$B$20,MATCH(J32,Roles!$A$17:$A$20,0)),1) | L32: 1 | M32: 1 | X32: 1 | Z32: =SUMPRODUCT(N32:Y32,$N$2:$Y$2)*$K32*$L32*$M32 | AA32: =SUM(N32:Y32) | AB32: =IFERROR(IF(UPPER($E32)="L",SUMPRODUCT(N32:Y32,$N$3:$Y$3,$N$2:$Y$2),SUMPRODUCT(N32:Y32,$N$4:$Y$4,$N$2:$Y$2))/(Z32/($K32*$L32*$M32)),"")
A33: 805904 | B33: Zach Cole | C33: HOU | D33: 26 | E33: L | F33: LF | G33: 53 | H33: 105 | I33: Bench Bat | J33: Opening Day | K33: =IFERROR(INDEX(Roles!$B$17:$B$20,MATCH(J33,Roles!$A$17:$A$20,0)),1) | L33: 1 | M33: 1 | W33: 1 | Z33: =SUMPRODUCT(N33:Y33,$N$2:$Y$2)*$K33*$L33*$M33 | AA33: =SUM(N33:Y33) | AB33: =IFERROR(IF(UPPER($E33)="L",SUMPRODUCT(N33:Y33,$N$3:$Y$3,$N$2:$Y$2),SUMPRODUCT(N33:Y33,$N$4:$Y$4,$N$2:$Y$2))/(Z33/($K33*$L33*$M33)),"")
A34: 553993 | B34: Eugenio Suárez | C34: CIN | D34: 35 | E34: R | F34: 3B | G34: 498 | H34: 3118 | I34: Everyday DH / 1B-DH | J34: Opening Day | K34: =IFERROR(INDEX(Roles!$B$17:$B$20,MATCH(J34,Roles!$A$17:$A$20,0)),1) | L34: 1 | M34: 1.0939475 | O34: 1 | Z34: =SUMPRODUCT(N34:Y34,$N$2:$Y$2)*$K34*$L34*$M34 | AA34: =SUM(N34:Y34) | AB34: =IFERROR(IF(UPPER($E34)="L",SUMPRODUCT(N34:Y34,$N$3:$Y$3,$N$2:$Y$2),SUMPRODUCT(N34:Y34,$N$4:$Y$4,$N$2:$Y$2))/(Z34/($K34*$L34*$M34)),"")
A35: 691718 | B35: Pete Crow-Armstrong | C35: CHC | D35: 25 | E35: L | F35: CF | G35: 726 | H35: 1802 | I35: Full Time | J35: Opening Day | K35: =IFERROR(INDEX(Roles!$B$17:$B$20,MATCH(J35,Roles!$A$17:$A$20,0)),1) | L35: 1 | M35: 1.15 | N35: 1 | Z35: =SUMPRODUCT(N35:Y35,$N$2:$Y$2)*$K35*$L35*$M35 | AA35: =SUM(N35:Y35) | AB35: =IFERROR(IF(UPPER($E35)="L",SUMPRODUCT(N35:Y35,$N$3:$Y$3,$N$2:$Y$2),SUMPRODUCT(N35:Y35,$N$4:$Y$4,$N$2:$Y$2))/(Z35/($K35*$L35*$M35)),"")
A36: 624414 | B36: Christian Arroyo | C36: BOS | D36: 32 | E36: R | F36: 2B | G36: 206 | H36: 506 | I36: Depth (no MLB PA) | J36: Opening Day | K36: =IFERROR(INDEX(Roles!$B$17:$B$20,MATCH(J36,Roles!$A$17:$A$20,0)),1) | L36: 1 | M36: 1 | Y36: 1 | Z36: =SUMPRODUCT(N36:Y36,$N$2:$Y$2)*$K36*$L36*$M36 | AA36: =SUM(N36:Y36) | AB36: =IFERROR(IF(UPPER($E36)="L",SUMPRODUCT(N36:Y36,$N$3:$Y$3,$N$2:$Y$2),SUMPRODUCT(N36:Y36,$N$4:$Y$4,$N$2:$Y$2))/(Z36/($K36*$L36*$M36)),"")
A37: 621311 | B37: David Dahl | C37: PHI | D37: 33 | E37: L | F37: LF | G37: 62 | H37: 71 | I37: Depth (no MLB PA) | J37: Opening Day | K37: =IFERROR(INDEX(Roles!$B$17:$B$20,MATCH(J37,Roles!$A$17:$A$20,0)),1) | L37: 1 | M37: 1 | Y37: 1 | Z37: =SUMPRODUCT(N37:Y37,$N$2:$Y$2)*$K37*$L37*$M37 | AA37: =SUM(N37:Y37) | AB37: =IFERROR(IF(UPPER($E37)="L",SUMPRODUCT(N37:Y37,$N$3:$Y$3,$N$2:$Y$2),SUMPRODUCT(N37:Y37,$N$4:$Y$4,$N$2:$Y$2))/(Z37/($K37*$L37*$M37)),"")
A38: 669398 | B38: Gage Workman | C38: SD | D38: 27 | E38: L | F38: 3B | G38: 41 | H38: 58 | I38: Bench Bat | J38: Opening Day | K38: =IFERROR(INDEX(Roles!$B$17:$B$20,MATCH(J38,Roles!$A$17:$A$20,0)),1) | L38: 1 | M38: 1 | W38: 1 | Z38: =SUMPRODUCT(N38:Y38,$N$2:$Y$2)*$K38*$L38*$M38 | AA38: =SUM(N38:Y38) | AB38: =IFERROR(IF(UPPER($E38)="L",SUMPRODUCT(N38:Y38,$N$3:$Y$3,$N$2:$Y$2),SUMPRODUCT(N38:Y38,$N$4:$Y$4,$N$2:$Y$2))/(Z38/($K38*$L38*$M38)),"")
A39: 672960 | B39: Kazuma Okamoto | C39: TOR | D39: 31 | E39: R | F39: 3B | G39: 636 | H39: 636 | I39: Full Time | J39: Opening Day | K39: =IFERROR(INDEX(Roles!$B$17:$B$20,MATCH(J39,Roles!$A$17:$A$20,0)),1) | L39: 1 | M39: 1.0790302 | N39: 1 | Z39: =SUMPRODUCT(N39:Y39,$N$2:$Y$2)*$K39*$L39*$M39 | AA39: =SUM(N39:Y39) | AB39: =IFERROR(IF(UPPER($E39)="L",SUMPRODUCT(N39:Y39,$N$3:$Y$3,$N$2:$Y$2),SUMPRODUCT(N39:Y39,$N$4:$Y$4,$N$2:$Y$2))/(Z39/($K39*$L39*$M39)),"")
A40: 672359 | B40: Tirso Ornelas | C40: SD | D40: 27 | E40: L | F40: LF | G40: 16 | H40: 16 | I40: Depth (no MLB PA) | J40: Opening Day | K40: =IFERROR(INDEX(Roles!$B$17:$B$20,MATCH(J40,Roles!$A$17:$A$20,0)),1) | L40: 1 | M40: 1 | Y40: 1 | Z40: =SUMPRODUCT(N40:Y40,$N$2:$Y$2)*$K40*$L40*$M40 | AA40: =SUM(N40:Y40) | AB40: =IFERROR(IF(UPPER($E40)="L",SUMPRODUCT(N40:Y40,$N$3:$Y$3,$N$2:$Y$2),SUMPRODUCT(N40:Y40,$N$4:$Y$4,$N$2:$Y$2))/(Z40/($K40*$L40*$M40)),"")
...

Sheet Roles
A1: Role | B1: PA Anchor | C1: vL Share (LHB) | D1: vL Share (RHB) | E1: Definition / notes
A2: Full Time | B2: 630 | C2: 0.26 | D2: 0.29 | E2: Everyday regular, ~150 games. Sees the league handedness mix.
A3: Everyday DH / 1B-DH | B3: 600 | C3: 0.26 | D3: 0.29 | E3: Rarely rested, no defensive injury exposure.
A4: Strong Side Platoon | B4: 480 | C4: 0.12 | D4: 0.45 | E4: The high-volume half of a platoon — usually a LHB who sits against LHP. Plays the majority of games.
A5: Weak Side Platoon | B5: 230 | C5: 0.08 | D5: 0.68 | E5: The low-volume half — usually a RHB who plays mostly against LHP. Only ~28% of league PA are vs LHP, which caps his volume.
A6: Catcher - Primary | B6: 500 | C6: 0.26 | D6: 0.29 | E6: CATCHERS HAVE THEIR OWN LADDER. A full-time catcher is ~500 PA, not 630 — applying the Full Time anchor over-projects every catcher in baseball by ~120 PA.
A7: Catcher - Tandem | B7: 340 | C7: 0.22 | D7: 0.38 | E7: Roughly even split with a partner; often matchup-managed.
A8: Catcher - Backup | B8: 180 | C8: 0.24 | D8: 0.33 | E8: Clear #2, starts ~45-55 games.
A9: Utility IF | B9: 290 | C9: 0.26 | D9: 0.31 | E9: Covers multiple infield spots; volume depends on incumbents' health.
A10: Utility OF / 4th OF | B10: 300 | C10: 0.24 | D10: 0.33 | E10: Distinct from Utility IF — different volume and platoon usage.
A11: Bench Bat | B11: 150 | C11: 0.22 | D11: 0.36 | E11: Pinch-hits and spot starts.
A12: Injury Replacement / 26th Man | B12: 90 | C12: 0.26 | D12: 0.29 | E12: Plays only when someone ahead of him is hurt. His volume is conditional on OTHER players' injuries — a team-level coupling that ultimately needs simulating, not a point estimate.
A13: Depth (no MLB PA) | B13: 1 | C13: 0.26 | D13: 0.29 | E13: Organizational depth. Hits the 1 PA floor (PT_FLOOR_PA) so he stays present and joinable without moving any aggregate.
A15: Role Start -> Role Share
A16: Role Start | B16: Role Share | C16: Meaning
A17: Opening Day | B17: 1 | C17: On the roster from day one.
A18: Early Season (~May) | B18: 0.8 | C18: Called up or activated in April/May.
A19: Mid Season (~July) | B19: 0.5 | C19: Mid-season callup, or back from a long IL stay.
A20: Late Season (~Sept) | B20: 0.2 | C20: September callup / late activation.
A22: Anchors are per 162 team games at full availability with the role held all season. Multiply by Role Share and Availability.

Sheet Teams
A1: Team | B1: pa_share | C1: Expected signing / note
A2: ARI | B2: 0
A3: ATL | B3: 0
A4: BAL | B4: 0
A5: BOS | B5: 0
A6: CHC | B6: 0
A7: CIN | B7: 0
A8: CLE | B8: 0
A9: COL | B9: 0
A10: CWS | B10: 0
A11: DET | B11: 0
A12: HOU | B12: 0
A13: KC | B13: 0
... A31: WSH | B31: 0
A33: Fraction of each club's PA budget held back for a signing it has not made yet. 0 to 0.5.
A34: Without a reserve the allocator spreads the full budget across the players currently on hand, so every incumbent absorbs the playing time that will actually go to the free agent.
A35: A reserve says 'this club's playing time is not all accounted for'. It does NOT say the club is better than its roster looks — the quality of an unsigned player is unknowable, so reserves never touch the rate projections.
A36: Copy these into the "reserves" block of rosters/team_assignments_<year>.json, which is what the pipeline reads.
